Traceback (most recent call last):
  File "/Users/petercharlton/anaconda3/lib/python3.8/site-packages/jupyter_cache/executors/utils.py", line 51, in single_nb_execution
    executenb(
  File "/Users/petercharlton/anaconda3/lib/python3.8/site-packages/nbclient/client.py", line 1112, in execute
    return NotebookClient(nb=nb, resources=resources, km=km, **kwargs).execute()
  File "/Users/petercharlton/anaconda3/lib/python3.8/site-packages/nbclient/util.py", line 74, in wrapped
    return just_run(coro(*args, **kwargs))
  File "/Users/petercharlton/anaconda3/lib/python3.8/site-packages/nbclient/util.py", line 53, in just_run
    return loop.run_until_complete(coro)
  File "/Users/petercharlton/anaconda3/lib/python3.8/asyncio/base_events.py", line 616, in run_until_complete
    return future.result()
  File "/Users/petercharlton/anaconda3/lib/python3.8/site-packages/nbclient/client.py", line 553, in async_execute
    await self.async_execute_cell(
  File "/Users/petercharlton/anaconda3/lib/python3.8/site-packages/nbclient/client.py", line 857, in async_execute_cell
    self._check_raise_for_error(cell, exec_reply)
  File "/Users/petercharlton/anaconda3/lib/python3.8/site-packages/nbclient/client.py", line 760, in _check_raise_for_error
    raise CellExecutionError.from_cell_and_msg(cell, exec_reply_content)
nbclient.exceptions.CellExecutionError: An error occurred while executing the following cell:
------------------
# load data from this record
start_seconds = 0
no_seconds_to_load = 5
fs = 125
record_data = wfdb.rdrecord(record_name=selected_record, sampfrom=fs*start_seconds, sampto=fs*(start_seconds+no_seconds_to_load), pn_dir=database_name) 
print("{} seconds of data loaded from: {}".format(no_seconds_to_load, selected_record))
------------------

[0;31m---------------------------------------------------------------------------[0m
[0;31mgaierror[0m                                  Traceback (most recent call last)
[0;32m~/anaconda3/lib/python3.8/site-packages/urllib3/connection.py[0m in [0;36m_new_conn[0;34m(self)[0m
[1;32m    168[0m         [0;32mtry[0m[0;34m:[0m[0;34m[0m[0;34m[0m[0m
[0;32m--> 169[0;31m             conn = connection.create_connection(
[0m[1;32m    170[0m                 [0;34m([0m[0mself[0m[0;34m.[0m[0m_dns_host[0m[0;34m,[0m [0mself[0m[0;34m.[0m[0mport[0m[0;34m)[0m[0;34m,[0m [0mself[0m[0;34m.[0m[0mtimeout[0m[0;34m,[0m [0;34m**[0m[0mextra_kw[0m[0;34m[0m[0;34m[0m[0m

[0;32m~/anaconda3/lib/python3.8/site-packages/urllib3/util/connection.py[0m in [0;36mcreate_connection[0;34m(address, timeout, source_address, socket_options)[0m
[1;32m     72[0m [0;34m[0m[0m
[0;32m---> 73[0;31m     [0;32mfor[0m [0mres[0m [0;32min[0m [0msocket[0m[0;34m.[0m[0mgetaddrinfo[0m[0;34m([0m[0mhost[0m[0;34m,[0m [0mport[0m[0;34m,[0m [0mfamily[0m[0;34m,[0m [0msocket[0m[0;34m.[0m[0mSOCK_STREAM[0m[0;34m)[0m[0;34m:[0m[0;34m[0m[0;34m[0m[0m
[0m[1;32m     74[0m         [0maf[0m[0;34m,[0m [0msocktype[0m[0;34m,[0m [0mproto[0m[0;34m,[0m [0mcanonname[0m[0;34m,[0m [0msa[0m [0;34m=[0m [0mres[0m[0;34m[0m[0;34m[0m[0m

[0;32m~/anaconda3/lib/python3.8/socket.py[0m in [0;36mgetaddrinfo[0;34m(host, port, family, type, proto, flags)[0m
[1;32m    917[0m     [0maddrlist[0m [0;34m=[0m [0;34m[[0m[0;34m][0m[0;34m[0m[0;34m[0m[0m
[0;32m--> 918[0;31m     [0;32mfor[0m [0mres[0m [0;32min[0m [0m_socket[0m[0;34m.[0m[0mgetaddrinfo[0m[0;34m([0m[0mhost[0m[0;34m,[0m [0mport[0m[0;34m,[0m [0mfamily[0m[0;34m,[0m [0mtype[0m[0;34m,[0m [0mproto[0m[0;34m,[0m [0mflags[0m[0;34m)[0m[0;34m:[0m[0;34m[0m[0;34m[0m[0m
[0m[1;32m    919[0m         [0maf[0m[0;34m,[0m [0msocktype[0m[0;34m,[0m [0mproto[0m[0;34m,[0m [0mcanonname[0m[0;34m,[0m [0msa[0m [0;34m=[0m [0mres[0m[0;34m[0m[0;34m[0m[0m

[0;31mgaierror[0m: [Errno 8] nodename nor servname provided, or not known

During handling of the above exception, another exception occurred:

[0;31mNewConnectionError[0m                        Traceback (most recent call last)
[0;32m~/anaconda3/lib/python3.8/site-packages/urllib3/connectionpool.py[0m in [0;36murlopen[0;34m(self, method, url, body, headers, retries, redirect, assert_same_host, timeout, pool_timeout, release_conn, chunked, body_pos, **response_kw)[0m
[1;32m    698[0m             [0;31m# Make the request on the httplib connection object.[0m[0;34m[0m[0;34m[0m[0;34m[0m[0m
[0;32m--> 699[0;31m             httplib_response = self._make_request(
[0m[1;32m    700[0m                 [0mconn[0m[0;34m,[0m[0;34m[0m[0;34m[0m[0m

[0;32m~/anaconda3/lib/python3.8/site-packages/urllib3/connectionpool.py[0m in [0;36m_make_request[0;34m(self, conn, method, url, timeout, chunked, **httplib_request_kw)[0m
[1;32m    381[0m         [0;32mtry[0m[0;34m:[0m[0;34m[0m[0;34m[0m[0m
[0;32m--> 382[0;31m             [0mself[0m[0;34m.[0m[0m_validate_conn[0m[0;34m([0m[0mconn[0m[0;34m)[0m[0;34m[0m[0;34m[0m[0m
[0m[1;32m    383[0m         [0;32mexcept[0m [0;34m([0m[0mSocketTimeout[0m[0;34m,[0m [0mBaseSSLError[0m[0;34m)[0m [0;32mas[0m [0me[0m[0;34m:[0m[0;34m[0m[0;34m[0m[0m

[0;32m~/anaconda3/lib/python3.8/site-packages/urllib3/connectionpool.py[0m in [0;36m_validate_conn[0;34m(self, conn)[0m
[1;32m   1009[0m         [0;32mif[0m [0;32mnot[0m [0mgetattr[0m[0;34m([0m[0mconn[0m[0;34m,[0m [0;34m"sock"[0m[0;34m,[0m [0;32mNone[0m[0;34m)[0m[0;34m:[0m  [0;31m# AppEngine might not have  `.sock`[0m[0;34m[0m[0;34m[0m[0m
[0;32m-> 1010[0;31m             [0mconn[0m[0;34m.[0m[0mconnect[0m[0;34m([0m[0;34m)[0m[0;34m[0m[0;34m[0m[0m
[0m[1;32m   1011[0m [0;34m[0m[0m

[0;32m~/anaconda3/lib/python3.8/site-packages/urllib3/connection.py[0m in [0;36mconnect[0;34m(self)[0m
[1;32m    352[0m         [0;31m# Add certificate verification[0m[0;34m[0m[0;34m[0m[0;34m[0m[0m
[0;32m--> 353[0;31m         [0mconn[0m [0;34m=[0m [0mself[0m[0;34m.[0m[0m_new_conn[0m[0;34m([0m[0;34m)[0m[0;34m[0m[0;34m[0m[0m
[0m[1;32m    354[0m         [0mhostname[0m [0;34m=[0m [0mself[0m[0;34m.[0m[0mhost[0m[0;34m[0m[0;34m[0m[0m

[0;32m~/anaconda3/lib/python3.8/site-packages/urllib3/connection.py[0m in [0;36m_new_conn[0;34m(self)[0m
[1;32m    180[0m         [0;32mexcept[0m [0mSocketError[0m [0;32mas[0m [0me[0m[0;34m:[0m[0;34m[0m[0;34m[0m[0m
[0;32m--> 181[0;31m             raise NewConnectionError(
[0m[1;32m    182[0m                 [0mself[0m[0;34m,[0m [0;34m"Failed to establish a new connection: %s"[0m [0;34m%[0m [0me[0m[0;34m[0m[0;34m[0m[0m

[0;31mNewConnectionError[0m: <urllib3.connection.HTTPSConnection object at 0x7fbc3b263f10>: Failed to establish a new connection: [Errno 8] nodename nor servname provided, or not known

During handling of the above exception, another exception occurred:

[0;31mMaxRetryError[0m                             Traceback (most recent call last)
[0;32m~/anaconda3/lib/python3.8/site-packages/requests/adapters.py[0m in [0;36msend[0;34m(self, request, stream, timeout, verify, cert, proxies)[0m
[1;32m    438[0m             [0;32mif[0m [0;32mnot[0m [0mchunked[0m[0;34m:[0m[0;34m[0m[0;34m[0m[0m
[0;32m--> 439[0;31m                 resp = conn.urlopen(
[0m[1;32m    440[0m                     [0mmethod[0m[0;34m=[0m[0mrequest[0m[0;34m.[0m[0mmethod[0m[0;34m,[0m[0;34m[0m[0;34m[0m[0m

[0;32m~/anaconda3/lib/python3.8/site-packages/urllib3/connectionpool.py[0m in [0;36murlopen[0;34m(self, method, url, body, headers, retries, redirect, assert_same_host, timeout, pool_timeout, release_conn, chunked, body_pos, **response_kw)[0m
[1;32m    754[0m [0;34m[0m[0m
[0;32m--> 755[0;31m             retries = retries.increment(
[0m[1;32m    756[0m                 [0mmethod[0m[0;34m,[0m [0murl[0m[0;34m,[0m [0merror[0m[0;34m=[0m[0me[0m[0;34m,[0m [0m_pool[0m[0;34m=[0m[0mself[0m[0;34m,[0m [0m_stacktrace[0m[0;34m=[0m[0msys[0m[0;34m.[0m[0mexc_info[0m[0;34m([0m[0;34m)[0m[0;34m[[0m[0;36m2[0m[0;34m][0m[0;34m[0m[0;34m[0m[0m

[0;32m~/anaconda3/lib/python3.8/site-packages/urllib3/util/retry.py[0m in [0;36mincrement[0;34m(self, method, url, response, error, _pool, _stacktrace)[0m
[1;32m    573[0m         [0;32mif[0m [0mnew_retry[0m[0;34m.[0m[0mis_exhausted[0m[0;34m([0m[0;34m)[0m[0;34m:[0m[0;34m[0m[0;34m[0m[0m
[0;32m--> 574[0;31m             [0;32mraise[0m [0mMaxRetryError[0m[0;34m([0m[0m_pool[0m[0;34m,[0m [0murl[0m[0;34m,[0m [0merror[0m [0;32mor[0m [0mResponseError[0m[0;34m([0m[0mcause[0m[0;34m)[0m[0;34m)[0m[0;34m[0m[0;34m[0m[0m
[0m[1;32m    575[0m [0;34m[0m[0m

[0;31mMaxRetryError[0m: HTTPSConnectionPool(host='physionet.org', port=443): Max retries exceeded with url: /files/mimic3wdb/1.0/30/3000063/3000063_0013.hea (Caused by NewConnectionError('<urllib3.connection.HTTPSConnection object at 0x7fbc3b263f10>: Failed to establish a new connection: [Errno 8] nodename nor servname provided, or not known'))

During handling of the above exception, another exception occurred:

[0;31mConnectionError[0m                           Traceback (most recent call last)
[0;32m<ipython-input-3-3345b3c7c5e8>[0m in [0;36m<module>[0;34m[0m
[1;32m      3[0m [0mno_seconds_to_load[0m [0;34m=[0m [0;36m5[0m[0;34m[0m[0;34m[0m[0m
[1;32m      4[0m [0mfs[0m [0;34m=[0m [0;36m125[0m[0;34m[0m[0;34m[0m[0m
[0;32m----> 5[0;31m [0mrecord_data[0m [0;34m=[0m [0mwfdb[0m[0;34m.[0m[0mrdrecord[0m[0;34m([0m[0mrecord_name[0m[0;34m=[0m[0mselected_record[0m[0;34m,[0m [0msampfrom[0m[0;34m=[0m[0mfs[0m[0;34m*[0m[0mstart_seconds[0m[0;34m,[0m [0msampto[0m[0;34m=[0m[0mfs[0m[0;34m*[0m[0;34m([0m[0mstart_seconds[0m[0;34m+[0m[0mno_seconds_to_load[0m[0;34m)[0m[0;34m,[0m [0mpn_dir[0m[0;34m=[0m[0mdatabase_name[0m[0;34m)[0m[0;34m[0m[0;34m[0m[0m
[0m[1;32m      6[0m [0mprint[0m[0;34m([0m[0;34m"{} seconds of data loaded from: {}"[0m[0;34m.[0m[0mformat[0m[0;34m([0m[0mno_seconds_to_load[0m[0;34m,[0m [0mselected_record[0m[0;34m)[0m[0;34m)[0m[0;34m[0m[0;34m[0m[0m

[0;32m~/anaconda3/lib/python3.8/site-packages/wfdb/io/record.py[0m in [0;36mrdrecord[0;34m(record_name, sampfrom, sampto, channels, physical, pn_dir, m2s, smooth_frames, ignore_skew, return_res, force_channels, channel_names, warn_empty)[0m
[1;32m   3431[0m         [0mrecord[0m [0;34m=[0m [0mwav2mit[0m[0;34m([0m[0mrecord_name[0m[0;34m,[0m [0mpn_dir[0m[0;34m=[0m[0mpn_dir[0m[0;34m,[0m [0mrecord_only[0m[0;34m=[0m[0;32mTrue[0m[0;34m)[0m[0;34m[0m[0;34m[0m[0m
[1;32m   3432[0m     [0;32melse[0m[0;34m:[0m[0;34m[0m[0;34m[0m[0m
[0;32m-> 3433[0;31m         [0mrecord[0m [0;34m=[0m [0mrdheader[0m[0;34m([0m[0mrecord_name[0m[0;34m,[0m [0mpn_dir[0m[0;34m=[0m[0mpn_dir[0m[0;34m,[0m [0mrd_segments[0m[0;34m=[0m[0;32mFalse[0m[0;34m)[0m[0;34m[0m[0;34m[0m[0m
[0m[1;32m   3434[0m [0;34m[0m[0m
[1;32m   3435[0m     [0;31m# Set defaults for sampto and channels input variables[0m[0;34m[0m[0;34m[0m[0;34m[0m[0m

[0;32m~/anaconda3/lib/python3.8/site-packages/wfdb/io/record.py[0m in [0;36mrdheader[0;34m(record_name, pn_dir, rd_segments)[0m
[1;32m   3257[0m [0;34m[0m[0m
[1;32m   3258[0m     [0;31m# Read the header file. Separate comment and non-comment lines[0m[0;34m[0m[0;34m[0m[0;34m[0m[0m
[0;32m-> 3259[0;31m     header_lines, comment_lines = _header._read_header_lines(base_record_name,
[0m[1;32m   3260[0m                                                              dir_name, pn_dir)
[1;32m   3261[0m [0;34m[0m[0m

[0;32m~/anaconda3/lib/python3.8/site-packages/wfdb/io/_header.py[0m in [0;36m_read_header_lines[0;34m(base_record_name, dir_name, pn_dir)[0m
[1;32m    855[0m     [0;31m# Read online header file[0m[0;34m[0m[0;34m[0m[0;34m[0m[0m
[1;32m    856[0m     [0;32melse[0m[0;34m:[0m[0;34m[0m[0;34m[0m[0m
[0;32m--> 857[0;31m         header_lines, comment_lines = download._stream_header(file_name,
[0m[1;32m    858[0m                                                               pn_dir)
[1;32m    859[0m [0;34m[0m[0m

[0;32m~/anaconda3/lib/python3.8/site-packages/wfdb/io/download.py[0m in [0;36m_stream_header[0;34m(file_name, pn_dir)[0m
[1;32m    109[0m     [0;31m# Full url of header location[0m[0;34m[0m[0;34m[0m[0;34m[0m[0m
[1;32m    110[0m     [0murl[0m [0;34m=[0m [0mposixpath[0m[0;34m.[0m[0mjoin[0m[0;34m([0m[0mconfig[0m[0;34m.[0m[0mdb_index_url[0m[0;34m,[0m [0mpn_dir[0m[0;34m,[0m [0mfile_name[0m[0;34m)[0m[0;34m[0m[0;34m[0m[0m
[0;32m--> 111[0;31m     [0mresponse[0m [0;34m=[0m [0mrequests[0m[0;34m.[0m[0mget[0m[0;34m([0m[0murl[0m[0;34m)[0m[0;34m[0m[0;34m[0m[0m
[0m[1;32m    112[0m [0;34m[0m[0m
[1;32m    113[0m     [0;31m# Raise HTTPError if invalid url[0m[0;34m[0m[0;34m[0m[0;34m[0m[0m

[0;32m~/anaconda3/lib/python3.8/site-packages/requests/api.py[0m in [0;36mget[0;34m(url, params, **kwargs)[0m
[1;32m     74[0m [0;34m[0m[0m
[1;32m     75[0m     [0mkwargs[0m[0;34m.[0m[0msetdefault[0m[0;34m([0m[0;34m'allow_redirects'[0m[0;34m,[0m [0;32mTrue[0m[0;34m)[0m[0;34m[0m[0;34m[0m[0m
[0;32m---> 76[0;31m     [0;32mreturn[0m [0mrequest[0m[0;34m([0m[0;34m'get'[0m[0;34m,[0m [0murl[0m[0;34m,[0m [0mparams[0m[0;34m=[0m[0mparams[0m[0;34m,[0m [0;34m**[0m[0mkwargs[0m[0;34m)[0m[0;34m[0m[0;34m[0m[0m
[0m[1;32m     77[0m [0;34m[0m[0m
[1;32m     78[0m [0;34m[0m[0m

[0;32m~/anaconda3/lib/python3.8/site-packages/requests/api.py[0m in [0;36mrequest[0;34m(method, url, **kwargs)[0m
[1;32m     59[0m     [0;31m# cases, and look like a memory leak in others.[0m[0;34m[0m[0;34m[0m[0;34m[0m[0m
[1;32m     60[0m     [0;32mwith[0m [0msessions[0m[0;34m.[0m[0mSession[0m[0;34m([0m[0;34m)[0m [0;32mas[0m [0msession[0m[0;34m:[0m[0;34m[0m[0;34m[0m[0m
[0;32m---> 61[0;31m         [0;32mreturn[0m [0msession[0m[0;34m.[0m[0mrequest[0m[0;34m([0m[0mmethod[0m[0;34m=[0m[0mmethod[0m[0;34m,[0m [0murl[0m[0;34m=[0m[0murl[0m[0;34m,[0m [0;34m**[0m[0mkwargs[0m[0;34m)[0m[0;34m[0m[0;34m[0m[0m
[0m[1;32m     62[0m [0;34m[0m[0m
[1;32m     63[0m [0;34m[0m[0m

[0;32m~/anaconda3/lib/python3.8/site-packages/requests/sessions.py[0m in [0;36mrequest[0;34m(self, method, url, params, data, headers, cookies, files, auth, timeout, allow_redirects, proxies, hooks, stream, verify, cert, json)[0m
[1;32m    540[0m         }
[1;32m    541[0m         [0msend_kwargs[0m[0;34m.[0m[0mupdate[0m[0;34m([0m[0msettings[0m[0;34m)[0m[0;34m[0m[0;34m[0m[0m
[0;32m--> 542[0;31m         [0mresp[0m [0;34m=[0m [0mself[0m[0;34m.[0m[0msend[0m[0;34m([0m[0mprep[0m[0;34m,[0m [0;34m**[0m[0msend_kwargs[0m[0;34m)[0m[0;34m[0m[0;34m[0m[0m
[0m[1;32m    543[0m [0;34m[0m[0m
[1;32m    544[0m         [0;32mreturn[0m [0mresp[0m[0;34m[0m[0;34m[0m[0m

[0;32m~/anaconda3/lib/python3.8/site-packages/requests/sessions.py[0m in [0;36msend[0;34m(self, request, **kwargs)[0m
[1;32m    653[0m [0;34m[0m[0m
[1;32m    654[0m         [0;31m# Send the request[0m[0;34m[0m[0;34m[0m[0;34m[0m[0m
[0;32m--> 655[0;31m         [0mr[0m [0;34m=[0m [0madapter[0m[0;34m.[0m[0msend[0m[0;34m([0m[0mrequest[0m[0;34m,[0m [0;34m**[0m[0mkwargs[0m[0;34m)[0m[0;34m[0m[0;34m[0m[0m
[0m[1;32m    656[0m [0;34m[0m[0m
[1;32m    657[0m         [0;31m# Total elapsed time of the request (approximately)[0m[0;34m[0m[0;34m[0m[0;34m[0m[0m

[0;32m~/anaconda3/lib/python3.8/site-packages/requests/adapters.py[0m in [0;36msend[0;34m(self, request, stream, timeout, verify, cert, proxies)[0m
[1;32m    514[0m                 [0;32mraise[0m [0mSSLError[0m[0;34m([0m[0me[0m[0;34m,[0m [0mrequest[0m[0;34m=[0m[0mrequest[0m[0;34m)[0m[0;34m[0m[0;34m[0m[0m
[1;32m    515[0m [0;34m[0m[0m
[0;32m--> 516[0;31m             [0;32mraise[0m [0mConnectionError[0m[0;34m([0m[0me[0m[0;34m,[0m [0mrequest[0m[0;34m=[0m[0mrequest[0m[0;34m)[0m[0;34m[0m[0;34m[0m[0m
[0m[1;32m    517[0m [0;34m[0m[0m
[1;32m    518[0m         [0;32mexcept[0m [0mClosedPoolError[0m [0;32mas[0m [0me[0m[0;34m:[0m[0;34m[0m[0;34m[0m[0m

[0;31mConnectionError[0m: HTTPSConnectionPool(host='physionet.org', port=443): Max retries exceeded with url: /files/mimic3wdb/1.0/30/3000063/3000063_0013.hea (Caused by NewConnectionError('<urllib3.connection.HTTPSConnection object at 0x7fbc3b263f10>: Failed to establish a new connection: [Errno 8] nodename nor servname provided, or not known'))
ConnectionError: HTTPSConnectionPool(host='physionet.org', port=443): Max retries exceeded with url: /files/mimic3wdb/1.0/30/3000063/3000063_0013.hea (Caused by NewConnectionError('<urllib3.connection.HTTPSConnection object at 0x7fbc3b263f10>: Failed to establish a new connection: [Errno 8] nodename nor servname provided, or not known'))

