Traceback (most recent call last):
  File "/Users/petercharlton/anaconda3/lib/python3.8/site-packages/jupyter_cache/executors/utils.py", line 51, in single_nb_execution
    executenb(
  File "/Users/petercharlton/anaconda3/lib/python3.8/site-packages/nbclient/client.py", line 1112, in execute
    return NotebookClient(nb=nb, resources=resources, km=km, **kwargs).execute()
  File "/Users/petercharlton/anaconda3/lib/python3.8/site-packages/nbclient/util.py", line 74, in wrapped
    return just_run(coro(*args, **kwargs))
  File "/Users/petercharlton/anaconda3/lib/python3.8/site-packages/nbclient/util.py", line 53, in just_run
    return loop.run_until_complete(coro)
  File "/Users/petercharlton/anaconda3/lib/python3.8/asyncio/base_events.py", line 616, in run_until_complete
    return future.result()
  File "/Users/petercharlton/anaconda3/lib/python3.8/site-packages/nbclient/client.py", line 553, in async_execute
    await self.async_execute_cell(
  File "/Users/petercharlton/anaconda3/lib/python3.8/site-packages/nbclient/client.py", line 857, in async_execute_cell
    self._check_raise_for_error(cell, exec_reply)
  File "/Users/petercharlton/anaconda3/lib/python3.8/site-packages/nbclient/client.py", line 760, in _check_raise_for_error
    raise CellExecutionError.from_cell_and_msg(cell, exec_reply_content)
nbclient.exceptions.CellExecutionError: An error occurred while executing the following cell:
------------------
# get a list of records in the database
database_name = 'mimic3wdb'
records = wfdb.get_record_list(database_name)
print("Loaded list of records for {} database".format(database_name))
------------------

[0;31m---------------------------------------------------------------------------[0m
[0;31mgaierror[0m                                  Traceback (most recent call last)
[0;32m~/anaconda3/lib/python3.8/site-packages/urllib3/connection.py[0m in [0;36m_new_conn[0;34m(self)[0m
[1;32m    168[0m         [0;32mtry[0m[0;34m:[0m[0;34m[0m[0;34m[0m[0m
[0;32m--> 169[0;31m             conn = connection.create_connection(
[0m[1;32m    170[0m                 [0;34m([0m[0mself[0m[0;34m.[0m[0m_dns_host[0m[0;34m,[0m [0mself[0m[0;34m.[0m[0mport[0m[0;34m)[0m[0;34m,[0m [0mself[0m[0;34m.[0m[0mtimeout[0m[0;34m,[0m [0;34m**[0m[0mextra_kw[0m[0;34m[0m[0;34m[0m[0m

[0;32m~/anaconda3/lib/python3.8/site-packages/urllib3/util/connection.py[0m in [0;36mcreate_connection[0;34m(address, timeout, source_address, socket_options)[0m
[1;32m     72[0m [0;34m[0m[0m
[0;32m---> 73[0;31m     [0;32mfor[0m [0mres[0m [0;32min[0m [0msocket[0m[0;34m.[0m[0mgetaddrinfo[0m[0;34m([0m[0mhost[0m[0;34m,[0m [0mport[0m[0;34m,[0m [0mfamily[0m[0;34m,[0m [0msocket[0m[0;34m.[0m[0mSOCK_STREAM[0m[0;34m)[0m[0;34m:[0m[0;34m[0m[0;34m[0m[0m
[0m[1;32m     74[0m         [0maf[0m[0;34m,[0m [0msocktype[0m[0;34m,[0m [0mproto[0m[0;34m,[0m [0mcanonname[0m[0;34m,[0m [0msa[0m [0;34m=[0m [0mres[0m[0;34m[0m[0;34m[0m[0m

[0;32m~/anaconda3/lib/python3.8/socket.py[0m in [0;36mgetaddrinfo[0;34m(host, port, family, type, proto, flags)[0m
[1;32m    917[0m     [0maddrlist[0m [0;34m=[0m [0;34m[[0m[0;34m][0m[0;34m[0m[0;34m[0m[0m
[0;32m--> 918[0;31m     [0;32mfor[0m [0mres[0m [0;32min[0m [0m_socket[0m[0;34m.[0m[0mgetaddrinfo[0m[0;34m([0m[0mhost[0m[0;34m,[0m [0mport[0m[0;34m,[0m [0mfamily[0m[0;34m,[0m [0mtype[0m[0;34m,[0m [0mproto[0m[0;34m,[0m [0mflags[0m[0;34m)[0m[0;34m:[0m[0;34m[0m[0;34m[0m[0m
[0m[1;32m    919[0m         [0maf[0m[0;34m,[0m [0msocktype[0m[0;34m,[0m [0mproto[0m[0;34m,[0m [0mcanonname[0m[0;34m,[0m [0msa[0m [0;34m=[0m [0mres[0m[0;34m[0m[0;34m[0m[0m

[0;31mgaierror[0m: [Errno 8] nodename nor servname provided, or not known

During handling of the above exception, another exception occurred:

[0;31mNewConnectionError[0m                        Traceback (most recent call last)
[0;32m~/anaconda3/lib/python3.8/site-packages/urllib3/connectionpool.py[0m in [0;36murlopen[0;34m(self, method, url, body, headers, retries, redirect, assert_same_host, timeout, pool_timeout, release_conn, chunked, body_pos, **response_kw)[0m
[1;32m    698[0m             [0;31m# Make the request on the httplib connection object.[0m[0;34m[0m[0;34m[0m[0;34m[0m[0m
[0;32m--> 699[0;31m             httplib_response = self._make_request(
[0m[1;32m    700[0m                 [0mconn[0m[0;34m,[0m[0;34m[0m[0;34m[0m[0m

[0;32m~/anaconda3/lib/python3.8/site-packages/urllib3/connectionpool.py[0m in [0;36m_make_request[0;34m(self, conn, method, url, timeout, chunked, **httplib_request_kw)[0m
[1;32m    381[0m         [0;32mtry[0m[0;34m:[0m[0;34m[0m[0;34m[0m[0m
[0;32m--> 382[0;31m             [0mself[0m[0;34m.[0m[0m_validate_conn[0m[0;34m([0m[0mconn[0m[0;34m)[0m[0;34m[0m[0;34m[0m[0m
[0m[1;32m    383[0m         [0;32mexcept[0m [0;34m([0m[0mSocketTimeout[0m[0;34m,[0m [0mBaseSSLError[0m[0;34m)[0m [0;32mas[0m [0me[0m[0;34m:[0m[0;34m[0m[0;34m[0m[0m

[0;32m~/anaconda3/lib/python3.8/site-packages/urllib3/connectionpool.py[0m in [0;36m_validate_conn[0;34m(self, conn)[0m
[1;32m   1009[0m         [0;32mif[0m [0;32mnot[0m [0mgetattr[0m[0;34m([0m[0mconn[0m[0;34m,[0m [0;34m"sock"[0m[0;34m,[0m [0;32mNone[0m[0;34m)[0m[0;34m:[0m  [0;31m# AppEngine might not have  `.sock`[0m[0;34m[0m[0;34m[0m[0m
[0;32m-> 1010[0;31m             [0mconn[0m[0;34m.[0m[0mconnect[0m[0;34m([0m[0;34m)[0m[0;34m[0m[0;34m[0m[0m
[0m[1;32m   1011[0m [0;34m[0m[0m

[0;32m~/anaconda3/lib/python3.8/site-packages/urllib3/connection.py[0m in [0;36mconnect[0;34m(self)[0m
[1;32m    352[0m         [0;31m# Add certificate verification[0m[0;34m[0m[0;34m[0m[0;34m[0m[0m
[0;32m--> 353[0;31m         [0mconn[0m [0;34m=[0m [0mself[0m[0;34m.[0m[0m_new_conn[0m[0;34m([0m[0;34m)[0m[0;34m[0m[0;34m[0m[0m
[0m[1;32m    354[0m         [0mhostname[0m [0;34m=[0m [0mself[0m[0;34m.[0m[0mhost[0m[0;34m[0m[0;34m[0m[0m

[0;32m~/anaconda3/lib/python3.8/site-packages/urllib3/connection.py[0m in [0;36m_new_conn[0;34m(self)[0m
[1;32m    180[0m         [0;32mexcept[0m [0mSocketError[0m [0;32mas[0m [0me[0m[0;34m:[0m[0;34m[0m[0;34m[0m[0m
[0;32m--> 181[0;31m             raise NewConnectionError(
[0m[1;32m    182[0m                 [0mself[0m[0;34m,[0m [0;34m"Failed to establish a new connection: %s"[0m [0;34m%[0m [0me[0m[0;34m[0m[0;34m[0m[0m

[0;31mNewConnectionError[0m: <urllib3.connection.HTTPSConnection object at 0x7f9787a57970>: Failed to establish a new connection: [Errno 8] nodename nor servname provided, or not known

During handling of the above exception, another exception occurred:

[0;31mMaxRetryError[0m                             Traceback (most recent call last)
[0;32m~/anaconda3/lib/python3.8/site-packages/requests/adapters.py[0m in [0;36msend[0;34m(self, request, stream, timeout, verify, cert, proxies)[0m
[1;32m    438[0m             [0;32mif[0m [0;32mnot[0m [0mchunked[0m[0;34m:[0m[0;34m[0m[0;34m[0m[0m
[0;32m--> 439[0;31m                 resp = conn.urlopen(
[0m[1;32m    440[0m                     [0mmethod[0m[0;34m=[0m[0mrequest[0m[0;34m.[0m[0mmethod[0m[0;34m,[0m[0;34m[0m[0;34m[0m[0m

[0;32m~/anaconda3/lib/python3.8/site-packages/urllib3/connectionpool.py[0m in [0;36murlopen[0;34m(self, method, url, body, headers, retries, redirect, assert_same_host, timeout, pool_timeout, release_conn, chunked, body_pos, **response_kw)[0m
[1;32m    754[0m [0;34m[0m[0m
[0;32m--> 755[0;31m             retries = retries.increment(
[0m[1;32m    756[0m                 [0mmethod[0m[0;34m,[0m [0murl[0m[0;34m,[0m [0merror[0m[0;34m=[0m[0me[0m[0;34m,[0m [0m_pool[0m[0;34m=[0m[0mself[0m[0;34m,[0m [0m_stacktrace[0m[0;34m=[0m[0msys[0m[0;34m.[0m[0mexc_info[0m[0;34m([0m[0;34m)[0m[0;34m[[0m[0;36m2[0m[0;34m][0m[0;34m[0m[0;34m[0m[0m

[0;32m~/anaconda3/lib/python3.8/site-packages/urllib3/util/retry.py[0m in [0;36mincrement[0;34m(self, method, url, response, error, _pool, _stacktrace)[0m
[1;32m    573[0m         [0;32mif[0m [0mnew_retry[0m[0;34m.[0m[0mis_exhausted[0m[0;34m([0m[0;34m)[0m[0;34m:[0m[0;34m[0m[0;34m[0m[0m
[0;32m--> 574[0;31m             [0;32mraise[0m [0mMaxRetryError[0m[0;34m([0m[0m_pool[0m[0;34m,[0m [0murl[0m[0;34m,[0m [0merror[0m [0;32mor[0m [0mResponseError[0m[0;34m([0m[0mcause[0m[0;34m)[0m[0;34m)[0m[0;34m[0m[0;34m[0m[0m
[0m[1;32m    575[0m [0;34m[0m[0m

[0;31mMaxRetryError[0m: HTTPSConnectionPool(host='physionet.org', port=443): Max retries exceeded with url: /content/mimic3wdb/ (Caused by NewConnectionError('<urllib3.connection.HTTPSConnection object at 0x7f9787a57970>: Failed to establish a new connection: [Errno 8] nodename nor servname provided, or not known'))

During handling of the above exception, another exception occurred:

[0;31mConnectionError[0m                           Traceback (most recent call last)
[0;32m<ipython-input-2-75055c5979f8>[0m in [0;36m<module>[0;34m[0m
[1;32m      1[0m [0;31m# get a list of records in the database[0m[0;34m[0m[0;34m[0m[0;34m[0m[0m
[1;32m      2[0m [0mdatabase_name[0m [0;34m=[0m [0;34m'mimic3wdb'[0m[0;34m[0m[0;34m[0m[0m
[0;32m----> 3[0;31m [0mrecords[0m [0;34m=[0m [0mwfdb[0m[0;34m.[0m[0mget_record_list[0m[0;34m([0m[0mdatabase_name[0m[0;34m)[0m[0;34m[0m[0;34m[0m[0m
[0m[1;32m      4[0m [0mprint[0m[0;34m([0m[0;34m"Loaded list of records for {} database"[0m[0;34m.[0m[0mformat[0m[0;34m([0m[0mdatabase_name[0m[0;34m)[0m[0;34m)[0m[0;34m[0m[0;34m[0m[0m

[0;32m~/anaconda3/lib/python3.8/site-packages/wfdb/io/download.py[0m in [0;36mget_record_list[0;34m(db_dir, records)[0m
[1;32m    280[0m     [0;31m# Full url PhysioNet database[0m[0;34m[0m[0;34m[0m[0;34m[0m[0m
[1;32m    281[0m     [0;32mif[0m [0;34m'/'[0m [0;32mnot[0m [0;32min[0m [0mdb_dir[0m[0;34m:[0m[0;34m[0m[0;34m[0m[0m
[0;32m--> 282[0;31m         [0mdb_url[0m [0;34m=[0m [0mposixpath[0m[0;34m.[0m[0mjoin[0m[0;34m([0m[0mconfig[0m[0;34m.[0m[0mdb_index_url[0m[0;34m,[0m [0mdb_dir[0m[0;34m,[0m [0mrecord[0m[0;34m.[0m[0mget_version[0m[0;34m([0m[0mdb_dir[0m[0;34m)[0m[0;34m)[0m[0;34m[0m[0;34m[0m[0m
[0m[1;32m    283[0m     [0;32melse[0m[0;34m:[0m[0;34m[0m[0;34m[0m[0m
[1;32m    284[0m         [0mdb_url[0m [0;34m=[0m [0mposixpath[0m[0;34m.[0m[0mjoin[0m[0;34m([0m[0mconfig[0m[0;34m.[0m[0mdb_index_url[0m[0;34m,[0m [0mdb_dir[0m[0;34m)[0m[0;34m[0m[0;34m[0m[0m

[0;32m~/anaconda3/lib/python3.8/site-packages/wfdb/io/record.py[0m in [0;36mget_version[0;34m(pn_dir)[0m
[1;32m   1245[0m     [0mdb_dir[0m [0;34m=[0m [0mpn_dir[0m[0;34m.[0m[0msplit[0m[0;34m([0m[0;34m'/'[0m[0;34m)[0m[0;34m[[0m[0;36m0[0m[0;34m][0m[0;34m[0m[0;34m[0m[0m
[1;32m   1246[0m     [0murl[0m [0;34m=[0m [0mposixpath[0m[0;34m.[0m[0mjoin[0m[0;34m([0m[0mdownload[0m[0;34m.[0m[0mPN_CONTENT_URL[0m[0;34m,[0m [0mdb_dir[0m[0;34m)[0m [0;34m+[0m [0;34m'/'[0m[0;34m[0m[0;34m[0m[0m
[0;32m-> 1247[0;31m     [0mresponse[0m [0;34m=[0m [0mrequests[0m[0;34m.[0m[0mget[0m[0;34m([0m[0murl[0m[0;34m)[0m[0;34m[0m[0;34m[0m[0m
[0m[1;32m   1248[0m     [0mcontents[0m [0;34m=[0m [0;34m[[0m[0mline[0m[0;34m.[0m[0mdecode[0m[0;34m([0m[0;34m'utf-8'[0m[0;34m)[0m[0;34m.[0m[0mstrip[0m[0;34m([0m[0;34m)[0m [0;32mfor[0m [0mline[0m [0;32min[0m [0mresponse[0m[0;34m.[0m[0mcontent[0m[0;34m.[0m[0msplitlines[0m[0;34m([0m[0;34m)[0m[0;34m][0m[0;34m[0m[0;34m[0m[0m
[1;32m   1249[0m     [0mversion_number[0m [0;34m=[0m [0;34m[[0m[0mv[0m [0;32mfor[0m [0mv[0m [0;32min[0m [0mcontents[0m [0;32mif[0m [0;34m'Version:'[0m [0;32min[0m [0mv[0m[0;34m][0m[0;34m[0m[0;34m[0m[0m

[0;32m~/anaconda3/lib/python3.8/site-packages/requests/api.py[0m in [0;36mget[0;34m(url, params, **kwargs)[0m
[1;32m     74[0m [0;34m[0m[0m
[1;32m     75[0m     [0mkwargs[0m[0;34m.[0m[0msetdefault[0m[0;34m([0m[0;34m'allow_redirects'[0m[0;34m,[0m [0;32mTrue[0m[0;34m)[0m[0;34m[0m[0;34m[0m[0m
[0;32m---> 76[0;31m     [0;32mreturn[0m [0mrequest[0m[0;34m([0m[0;34m'get'[0m[0;34m,[0m [0murl[0m[0;34m,[0m [0mparams[0m[0;34m=[0m[0mparams[0m[0;34m,[0m [0;34m**[0m[0mkwargs[0m[0;34m)[0m[0;34m[0m[0;34m[0m[0m
[0m[1;32m     77[0m [0;34m[0m[0m
[1;32m     78[0m [0;34m[0m[0m

[0;32m~/anaconda3/lib/python3.8/site-packages/requests/api.py[0m in [0;36mrequest[0;34m(method, url, **kwargs)[0m
[1;32m     59[0m     [0;31m# cases, and look like a memory leak in others.[0m[0;34m[0m[0;34m[0m[0;34m[0m[0m
[1;32m     60[0m     [0;32mwith[0m [0msessions[0m[0;34m.[0m[0mSession[0m[0;34m([0m[0;34m)[0m [0;32mas[0m [0msession[0m[0;34m:[0m[0;34m[0m[0;34m[0m[0m
[0;32m---> 61[0;31m         [0;32mreturn[0m [0msession[0m[0;34m.[0m[0mrequest[0m[0;34m([0m[0mmethod[0m[0;34m=[0m[0mmethod[0m[0;34m,[0m [0murl[0m[0;34m=[0m[0murl[0m[0;34m,[0m [0;34m**[0m[0mkwargs[0m[0;34m)[0m[0;34m[0m[0;34m[0m[0m
[0m[1;32m     62[0m [0;34m[0m[0m
[1;32m     63[0m [0;34m[0m[0m

[0;32m~/anaconda3/lib/python3.8/site-packages/requests/sessions.py[0m in [0;36mrequest[0;34m(self, method, url, params, data, headers, cookies, files, auth, timeout, allow_redirects, proxies, hooks, stream, verify, cert, json)[0m
[1;32m    540[0m         }
[1;32m    541[0m         [0msend_kwargs[0m[0;34m.[0m[0mupdate[0m[0;34m([0m[0msettings[0m[0;34m)[0m[0;34m[0m[0;34m[0m[0m
[0;32m--> 542[0;31m         [0mresp[0m [0;34m=[0m [0mself[0m[0;34m.[0m[0msend[0m[0;34m([0m[0mprep[0m[0;34m,[0m [0;34m**[0m[0msend_kwargs[0m[0;34m)[0m[0;34m[0m[0;34m[0m[0m
[0m[1;32m    543[0m [0;34m[0m[0m
[1;32m    544[0m         [0;32mreturn[0m [0mresp[0m[0;34m[0m[0;34m[0m[0m

[0;32m~/anaconda3/lib/python3.8/site-packages/requests/sessions.py[0m in [0;36msend[0;34m(self, request, **kwargs)[0m
[1;32m    653[0m [0;34m[0m[0m
[1;32m    654[0m         [0;31m# Send the request[0m[0;34m[0m[0;34m[0m[0;34m[0m[0m
[0;32m--> 655[0;31m         [0mr[0m [0;34m=[0m [0madapter[0m[0;34m.[0m[0msend[0m[0;34m([0m[0mrequest[0m[0;34m,[0m [0;34m**[0m[0mkwargs[0m[0;34m)[0m[0;34m[0m[0;34m[0m[0m
[0m[1;32m    656[0m [0;34m[0m[0m
[1;32m    657[0m         [0;31m# Total elapsed time of the request (approximately)[0m[0;34m[0m[0;34m[0m[0;34m[0m[0m

[0;32m~/anaconda3/lib/python3.8/site-packages/requests/adapters.py[0m in [0;36msend[0;34m(self, request, stream, timeout, verify, cert, proxies)[0m
[1;32m    514[0m                 [0;32mraise[0m [0mSSLError[0m[0;34m([0m[0me[0m[0;34m,[0m [0mrequest[0m[0;34m=[0m[0mrequest[0m[0;34m)[0m[0;34m[0m[0;34m[0m[0m
[1;32m    515[0m [0;34m[0m[0m
[0;32m--> 516[0;31m             [0;32mraise[0m [0mConnectionError[0m[0;34m([0m[0me[0m[0;34m,[0m [0mrequest[0m[0;34m=[0m[0mrequest[0m[0;34m)[0m[0;34m[0m[0;34m[0m[0m
[0m[1;32m    517[0m [0;34m[0m[0m
[1;32m    518[0m         [0;32mexcept[0m [0mClosedPoolError[0m [0;32mas[0m [0me[0m[0;34m:[0m[0;34m[0m[0;34m[0m[0m

[0;31mConnectionError[0m: HTTPSConnectionPool(host='physionet.org', port=443): Max retries exceeded with url: /content/mimic3wdb/ (Caused by NewConnectionError('<urllib3.connection.HTTPSConnection object at 0x7f9787a57970>: Failed to establish a new connection: [Errno 8] nodename nor servname provided, or not known'))
ConnectionError: HTTPSConnectionPool(host='physionet.org', port=443): Max retries exceeded with url: /content/mimic3wdb/ (Caused by NewConnectionError('<urllib3.connection.HTTPSConnection object at 0x7f9787a57970>: Failed to establish a new connection: [Errno 8] nodename nor servname provided, or not known'))

