Traceback (most recent call last):
  File "/opt/hostedtoolcache/Python/3.9.13/x64/lib/python3.9/site-packages/jupyter_cache/executors/utils.py", line 51, in single_nb_execution
    executenb(
  File "/opt/hostedtoolcache/Python/3.9.13/x64/lib/python3.9/site-packages/nbclient/client.py", line 1204, in execute
    return NotebookClient(nb=nb, resources=resources, km=km, **kwargs).execute()
  File "/opt/hostedtoolcache/Python/3.9.13/x64/lib/python3.9/site-packages/nbclient/util.py", line 84, in wrapped
    return just_run(coro(*args, **kwargs))
  File "/opt/hostedtoolcache/Python/3.9.13/x64/lib/python3.9/site-packages/nbclient/util.py", line 62, in just_run
    return loop.run_until_complete(coro)
  File "/opt/hostedtoolcache/Python/3.9.13/x64/lib/python3.9/asyncio/base_events.py", line 647, in run_until_complete
    return future.result()
  File "/opt/hostedtoolcache/Python/3.9.13/x64/lib/python3.9/site-packages/nbclient/client.py", line 663, in async_execute
    await self.async_execute_cell(
  File "/opt/hostedtoolcache/Python/3.9.13/x64/lib/python3.9/site-packages/nbclient/client.py", line 965, in async_execute_cell
    await self._check_raise_for_error(cell, cell_index, exec_reply)
  File "/opt/hostedtoolcache/Python/3.9.13/x64/lib/python3.9/site-packages/nbclient/client.py", line 862, in _check_raise_for_error
    raise CellExecutionError.from_cell_and_msg(cell, exec_reply_content)
nbclient.exceptions.CellExecutionError: An error occurred while executing the following cell:
------------------
temp_fs = 125
ppg_ibis_d2max = pulse_detect(ppg_filt,temp_fs,5,'d2max')
print("Detected {} beats in the PPG signal using the {} algorithm".format(len(ppg_ibis_d2max), "D2max"))
ppg_ibis_upslopes = pulse_detect(ppg_filt,temp_fs,5,'upslopes')
print("Detected {} beats in the PPG signal using the {} algorithm".format(len(ppg_ibis_upslopes), "Upslopes"))
ppg_ibis_delineator = pulse_detect(ppg_filt,temp_fs,5,'delineator')
print("Detected {} beats in the PPG signal using the {} algorithm".format(len(ppg_ibis_delineator), "Delineator"))
------------------

[0;31m---------------------------------------------------------------------------[0m
[0;31mNameError[0m                                 Traceback (most recent call last)
Input [0;32mIn [5][0m, in [0;36m<cell line: 2>[0;34m()[0m
[1;32m      1[0m temp_fs [38;5;241m=[39m [38;5;241m125[39m
[0;32m----> 2[0m ppg_ibis_d2max [38;5;241m=[39m [43mpulse_detect[49m(ppg_filt,temp_fs,[38;5;241m5[39m,[38;5;124m'[39m[38;5;124md2max[39m[38;5;124m'[39m)
[1;32m      3[0m [38;5;28mprint[39m([38;5;124m"[39m[38;5;124mDetected [39m[38;5;132;01m{}[39;00m[38;5;124m beats in the PPG signal using the [39m[38;5;132;01m{}[39;00m[38;5;124m algorithm[39m[38;5;124m"[39m[38;5;241m.[39mformat([38;5;28mlen[39m(ppg_ibis_d2max), [38;5;124m"[39m[38;5;124mD2max[39m[38;5;124m"[39m))
[1;32m      4[0m ppg_ibis_upslopes [38;5;241m=[39m pulse_detect(ppg_filt,temp_fs,[38;5;241m5[39m,[38;5;124m'[39m[38;5;124mupslopes[39m[38;5;124m'[39m)

[0;31mNameError[0m: name 'pulse_detect' is not defined
NameError: name 'pulse_detect' is not defined

